Traceback (most recent call last):
  File "/home/ubuntu/Documents/Claude/ADVERSARIAL_SIMULATIONS/INTEGRATION/agent_bridge.py", line 519, in <module>
    asyncio.run(main())
  File "/usr/lib/python3.12/asyncio/runners.py", line 194, in run
    return runner.run(main)
           ^^^^^^^^^^^^^^^^
  File "/usr/lib/python3.12/asyncio/runners.py", line 118, in run
    return self._loop.run_until_complete(task)
           ^^^^^^^^^^^^^^^^^^^^^^^^^^^^^^^^^^^
  File "/usr/lib/python3.12/asyncio/base_events.py", line 687, in run_until_complete
    return future.result()
           ^^^^^^^^^^^^^^^
  File "/home/ubuntu/Documents/Claude/ADVERSARIAL_SIMULATIONS/INTEGRATION/agent_bridge.py", line 504, in main
    bridge = AgentSimulationBridge()
             ^^^^^^^^^^^^^^^^^^^^^^^
  File "/home/ubuntu/Documents/Claude/ADVERSARIAL_SIMULATIONS/INTEGRATION/agent_bridge.py", line 60, in __init__
    self.agent_socket.bind(f"tcp://*:{agent_port}")
  File "/home/ubuntu/.local/lib/python3.12/site-packages/zmq/sugar/socket.py", line 320, in bind
    super().bind(addr)
  File "zmq/backend/cython/_zmq.py", line 998, in zmq.backend.cython._zmq.Socket.bind
  File "zmq/backend/cython/_zmq.py", line 187, in zmq.backend.cython._zmq._check_rc
zmq.error.ZMQError: Address already in use (addr='tcp://*:4242')
